<?xml version="1.0"?>
<robot name="hexapod">
  <link name="base">
    <inertial>
      <origin xyz="0 0 0" rpy="0 0 0"/>
      <mass value="6.0"/>
      <inertia ixx="0.02" ixy="0" ixz="0" iyy="0.02" iyz="0" izz="0.02"/>
    </inertial>
    <visual>
      <origin xyz="0 0 0" rpy="0 0 0"/>
      <geometry>
        <box size="0.35 0.25 0.08"/>
      </geometry>
    </visual>
    <collision>
      <origin xyz="0 0 0" rpy="0 0 0"/>
      <geometry>
        <box size="0.35 0.25 0.08"/>
      </geometry>
    </collision>
  </link>

  <link name="LF_hip_link"><visual><origin xyz="0.03 0 0" rpy="0 1.5708 0"/><geometry><cylinder length="0.06" radius="0.02"/></geometry></visual><collision><origin xyz="0.03 0 0" rpy="0 1.5708 0"/><geometry><cylinder length="0.06" radius="0.02"/></geometry></collision><inertial><mass value="0.3"/><inertia ixx="1e-3" iyy="1e-3" izz="1e-3"/></inertial></link>
  <link name="LF_thigh_link"><visual><origin xyz="0 0 -0.04" rpy="0 0 0"/><geometry><cylinder length="0.08" radius="0.02"/></geometry></visual><collision><origin xyz="0 0 -0.04" rpy="0 0 0"/><geometry><cylinder length="0.08" radius="0.02"/></geometry></collision><inertial><mass value="0.25"/><inertia ixx="8e-4" iyy="8e-4" izz="8e-4"/></inertial></link>
  <link name="LF_knee_link"><visual><origin xyz="0 0 -0.045" rpy="0 0 0"/><geometry><cylinder length="0.09" radius="0.02"/></geometry></visual><collision><origin xyz="0 0 -0.045" rpy="0 0 0"/><geometry><cylinder length="0.09" radius="0.02"/></geometry></collision><inertial><mass value="0.2"/><inertia ixx="6e-4" iyy="6e-4" izz="6e-4"/></inertial></link>
  <joint name="LF_HIP" type="revolute"><parent link="base"/><child link="LF_hip_link"/><origin xyz="0.18 0.15 0.02" rpy="0 0 0"/><axis xyz="0 0 1"/><limit lower="-1.0" upper="1.0" effort="5" velocity="4.0"/></joint>
  <joint name="LF_THIGH" type="revolute"><parent link="LF_hip_link"/><child link="LF_thigh_link"/><origin xyz="0.03 0 0" rpy="0 0 0"/><axis xyz="0 1 0"/><limit lower="-1.5" upper="1.5" effort="5" velocity="4.0"/></joint>
  <joint name="LF_KNEE" type="revolute"><parent link="LF_thigh_link"/><child link="LF_knee_link"/><origin xyz="0.0 0.0 -0.04" rpy="0 0 0"/><axis xyz="0 1 0"/><limit lower="-1.0" upper="1.0" effort="5" velocity="4.0"/></joint>

  <link name="LM_hip_link"><visual><origin xyz="0.03 0 0" rpy="0 1.5708 0"/><geometry><cylinder length="0.06" radius="0.02"/></geometry></visual><collision><origin xyz="0.03 0 0" rpy="0 1.5708 0"/><geometry><cylinder length="0.06" radius="0.02"/></geometry></collision><inertial><mass value="0.3"/><inertia ixx="1e-3" iyy="1e-3" izz="1e-3"/></inertial></link>
  <link name="LM_thigh_link"><visual><origin xyz="0 0 -0.04" rpy="0 0 0"/><geometry><cylinder length="0.08" radius="0.02"/></geometry></visual><collision><origin xyz="0 0 -0.04" rpy="0 0 0"/><geometry><cylinder length="0.08" radius="0.02"/></geometry></collision><inertial><mass value="0.25"/><inertia ixx="8e-4" iyy="8e-4" izz="8e-4"/></inertial></link>
  <link name="LM_knee_link"><visual><origin xyz="0 0 -0.045" rpy="0 0 0"/><geometry><cylinder length="0.09" radius="0.02"/></geometry></visual><collision><origin xyz="0 0 -0.045" rpy="0 0 0"/><geometry><cylinder length="0.09" radius="0.02"/></geometry></collision><inertial><mass value="0.2"/><inertia ixx="6e-4" iyy="6e-4" izz="6e-4"/></inertial></link>
  <joint name="LM_HIP" type="revolute"><parent link="base"/><child link="LM_hip_link"/><origin xyz="0.0 0.15 0.02" rpy="0 0 0"/><axis xyz="0 0 1"/><limit lower="-1.0" upper="1.0" effort="5" velocity="4.0"/></joint>
  <joint name="LM_THIGH" type="revolute"><parent link="LM_hip_link"/><child link="LM_thigh_link"/><origin xyz="0.03 0 0" rpy="0 0 0"/><axis xyz="0 1 0"/><limit lower="-1.5" upper="1.5" effort="5" velocity="4.0"/></joint>
  <joint name="LM_KNEE" type="revolute"><parent link="LM_thigh_link"/><child link="LM_knee_link"/><origin xyz="0.0 0.0 -0.04" rpy="0 0 0"/><axis xyz="0 1 0"/><limit lower="-1.0" upper="1.0" effort="5" velocity="4.0"/></joint>

  <link name="LR_hip_link"><visual><origin xyz="0.03 0 0" rpy="0 1.5708 0"/><geometry><cylinder length="0.06" radius="0.02"/></geometry></visual><collision><origin xyz="0.03 0 0" rpy="0 1.5708 0"/><geometry><cylinder length="0.06" radius="0.02"/></geometry></collision><inertial><mass value="0.3"/><inertia ixx="1e-3" iyy="1e-3" izz="1e-3"/></inertial></link>
  <link name="LR_thigh_link"><visual><origin xyz="0 0 -0.04" rpy="0 0 0"/><geometry><cylinder length="0.08" radius="0.02"/></geometry></visual><collision><origin xyz="0 0 -0.04" rpy="0 0 0"/><geometry><cylinder length="0.08" radius="0.02"/></geometry></collision><inertial><mass value="0.25"/><inertia ixx="8e-4" iyy="8e-4" izz="8e-4"/></inertial></link>
  <link name="LR_knee_link"><visual><origin xyz="0 0 -0.045" rpy="0 0 0"/><geometry><cylinder length="0.09" radius="0.02"/></geometry></visual><collision><origin xyz="0 0 -0.045" rpy="0 0 0"/><geometry><cylinder length="0.09" radius="0.02"/></geometry></collision><inertial><mass value="0.2"/><inertia ixx="6e-4" iyy="6e-4" izz="6e-4"/></inertial></link>
  <joint name="LR_HIP" type="revolute"><parent link="base"/><child link="LR_hip_link"/><origin xyz="-0.18 0.15 0.02" rpy="0 0 0"/><axis xyz="0 0 1"/><limit lower="-1.0" upper="1.0" effort="5" velocity="4.0"/></joint>
  <joint name="LR_THIGH" type="revolute"><parent link="LR_hip_link"/><child link="LR_thigh_link"/><origin xyz="0.03 0 0" rpy="0 0 0"/><axis xyz="0 1 0"/><limit lower="-1.5" upper="1.5" effort="5" velocity="4.0"/></joint>
  <joint name="LR_KNEE" type="revolute"><parent link="LR_thigh_link"/><child link="LR_knee_link"/><origin xyz="0.0 0.0 -0.04" rpy="0 0 0"/><axis xyz="0 1 0"/><limit lower="-1.0" upper="1.0" effort="5" velocity="4.0"/></joint>

  <link name="RF_hip_link"><visual><origin xyz="0.03 0 0" rpy="0 1.5708 0"/><geometry><cylinder length="0.06" radius="0.02"/></geometry></visual><collision><origin xyz="0.03 0 0" rpy="0 1.5708 0"/><geometry><cylinder length="0.06" radius="0.02"/></geometry></collision><inertial><mass value="0.3"/><inertia ixx="1e-3" iyy="1e-3" izz="1e-3"/></inertial></link>
  <link name="RF_thigh_link"><visual><origin xyz="0 0 -0.04" rpy="0 0 0"/><geometry><cylinder length="0.08" radius="0.02"/></geometry></visual><collision><origin xyz="0 0 -0.04" rpy="0 0 0"/><geometry><cylinder length="0.08" radius="0.02"/></geometry></collision><inertial><mass value="0.25"/><inertia ixx="8e-4" iyy="8e-4" izz="8e-4"/></inertial></link>
  <link name="RF_knee_link"><visual><origin xyz="0 0 -0.045" rpy="0 0 0"/><geometry><cylinder length="0.09" radius="0.02"/></geometry></visual><collision><origin xyz="0 0 -0.045" rpy="0 0 0"/><geometry><cylinder length="0.09" radius="0.02"/></geometry></collision><inertial><mass value="0.2"/><inertia ixx="6e-4" iyy="6e-4" izz="6e-4"/></inertial></link>
  <joint name="RF_HIP" type="revolute"><parent link="base"/><child link="RF_hip_link"/><origin xyz="0.18 -0.15 0.02" rpy="0 0 0"/><axis xyz="0 0 1"/><limit lower="-1.0" upper="1.0" effort="5" velocity="4.0"/></joint>
  <joint name="RF_THIGH" type="revolute"><parent link="RF_hip_link"/><child link="RF_thigh_link"/><origin xyz="0.03 0 0" rpy="0 0 0"/><axis xyz="0 1 0"/><limit lower="-1.5" upper="1.5" effort="5" velocity="4.0"/></joint>
  <joint name="RF_KNEE" type="revolute"><parent link="RF_thigh_link"/><child link="RF_knee_link"/><origin xyz="0.0 0.0 -0.04" rpy="0 0 0"/><axis xyz="0 1 0"/><limit lower="-1.0" upper="1.0" effort="5" velocity="4.0"/></joint>

  <link name="RM_hip_link"><visual><origin xyz="0.03 0 0" rpy="0 1.5708 0"/><geometry><cylinder length="0.06" radius="0.02"/></geometry></visual><collision><origin xyz="0.03 0 0" rpy="0 1.5708 0"/><geometry><cylinder length="0.06" radius="0.02"/></geometry></collision><inertial><mass value="0.3"/><inertia ixx="1e-3" iyy="1e-3" izz="1e-3"/></inertial></link>
  <link name="RM_thigh_link"><visual><origin xyz="0 0 -0.04" rpy="0 0 0"/><geometry><cylinder length="0.08" radius="0.02"/></geometry></visual><collision><origin xyz="0 0 -0.04" rpy="0 0 0"/><geometry><cylinder length="0.08" radius="0.02"/></geometry></collision><inertial><mass value="0.25"/><inertia ixx="8e-4" iyy="8e-4" izz="8e-4"/></inertial></link>
  <link name="RM_knee_link"><visual><origin xyz="0 0 -0.045" rpy="0 0 0"/><geometry><cylinder length="0.09" radius="0.02"/></geometry></visual><collision><origin xyz="0 0 -0.045" rpy="0 0 0"/><geometry><cylinder length="0.09" radius="0.02"/></geometry></collision><inertial><mass value="0.2"/><inertia ixx="6e-4" iyy="6e-4" izz="6e-4"/></inertial></link>
  <joint name="RM_HIP" type="revolute"><parent link="base"/><child link="RM_hip_link"/><origin xyz="0.0 -0.15 0.02" rpy="0 0 0"/><axis xyz="0 0 1"/><limit lower="-1.0" upper="1.0" effort="5" velocity="4.0"/></joint>
  <joint name="RM_THIGH" type="revolute"><parent link="RM_hip_link"/><child link="RM_thigh_link"/><origin xyz="0.03 0 0" rpy="0 0 0"/><axis xyz="0 1 0"/><limit lower="-1.5" upper="1.5" effort="5" velocity="4.0"/></joint>
  <joint name="RM_KNEE" type="revolute"><parent link="RM_thigh_link"/><child link="RM_knee_link"/><origin xyz="0.0 0.0 -0.04" rpy="0 0 0"/><axis xyz="0 1 0"/><limit lower="-1.0" upper="1.0" effort="5" velocity="4.0"/></joint>

  <link name="RR_hip_link"><visual><origin xyz="0.03 0 0" rpy="0 1.5708 0"/><geometry><cylinder length="0.06" radius="0.02"/></geometry></visual><collision><origin xyz="0.03 0 0" rpy="0 1.5708 0"/><geometry><cylinder length="0.06" radius="0.02"/></geometry></collision><inertial><mass value="0.3"/><inertia ixx="1e-3" iyy="1e-3" izz="1e-3"/></inertial></link>
  <link name="RR_thigh_link"><visual><origin xyz="0 0 -0.04" rpy="0 0 0"/><geometry><cylinder length="0.08" radius="0.02"/></geometry></visual><collision><origin xyz="0 0 -0.04" rpy="0 0 0"/><geometry><cylinder length="0.08" radius="0.02"/></geometry></collision><inertial><mass value="0.25"/><inertia ixx="8e-4" iyy="8e-4" izz="8e-4"/></inertial></link>
  <link name="RR_knee_link"><visual><origin xyz="0 0 -0.045" rpy="0 0 0"/><geometry><cylinder length="0.09" radius="0.02"/></geometry></visual><collision><origin xyz="0 0 -0.045" rpy="0 0 0"/><geometry><cylinder length="0.09" radius="0.02"/></geometry></collision><inertial><mass value="0.2"/><inertia ixx="6e-4" iyy="6e-4" izz="6e-4"/></inertial></link>
  <joint name="RR_HIP" type="revolute"><parent link="base"/><child link="RR_hip_link"/><origin xyz="-0.18 -0.15 0.02" rpy="0 0 0"/><axis xyz="0 0 1"/><limit lower="-1.0" upper="1.0" effort="5" velocity="4.0"/></joint>
  <joint name="RR_THIGH" type="revolute"><parent link="RR_hip_link"/><child link="RR_thigh_link"/><origin xyz="0.03 0 0" rpy="0 0 0"/><axis xyz="0 1 0"/><limit lower="-1.5" upper="1.5" effort="5" velocity="4.0"/></joint>
  <joint name="RR_KNEE" type="revolute"><parent link="RR_thigh_link"/><child link="RR_knee_link"/><origin xyz="0.0 0.0 -0.04" rpy="0 0 0"/><axis xyz="0 1 0"/><limit lower="-1.0" upper="1.0" effort="5" velocity="4.0"/></joint>

</robot>